<?xml version="1.0"?>
<robot name="delivery_bot">

  <!-- Base chassis -->
  <link name="base_link">
    <visual>
      <geometry>
        <box size="0.4 0.3 0.15"/> <!-- LxWxH in meters -->
      </geometry>
      <material name="gray">
        <color rgba="0.6 0.6 0.6 1"/>
      </material>
    </visual>
    <collision>
      <geometry>
        <box size="0.4 0.3 0.15"/>
      </geometry>
    </collision>
    <inertial>
      <mass value="5.0"/>
      <inertia ixx="0.1" ixy="0" ixz="0" iyy="0.1" iyz="0" izz="0.1"/>
    </inertial>
  </link>

  <!-- Rear left wheel -->
  <link name="rear_left_wheel"/>
  <joint name="rear_left_wheel_joint" type="continuous">
    <parent link="base_link"/>
    <child link="rear_left_wheel"/>
    <origin xyz="-0.15 0.12 0.03" rpy="0 0 0"/>
    <axis xyz="0 1 0"/>
  </joint>

  <!-- Rear right wheel -->
  <link name="rear_right_wheel"/>
  <joint name="rear_right_wheel_joint" type="continuous">
    <parent link="base_link"/>
    <child link="rear_right_wheel"/>
    <origin xyz="-0.15 -0.12 0.03" rpy="0 0 0"/>
    <axis xyz="0 1 0"/>
  </joint>

  <!-- Front left caster -->
  <link name="front_left_wheel"/>
  <joint name="front_left_wheel_joint" type="continuous">
    <parent link="base_link"/>
    <child link="front_left_wheel"/>
    <origin xyz="0.15 0.12 0.03" rpy="0 0 0"/>
    <axis xyz="0 0 1"/>
  </joint>

  <!-- Front right caster -->
  <link name="front_right_wheel"/>
  <joint name="front_right_wheel_joint" type="continuous">
    <parent link="base_link"/>
    <child link="front_right_wheel"/>
    <origin xyz="0.15 -0.12 0.03" rpy="0 0 0"/>
    <axis xyz="0 0 1"/>
  </joint>

  <!-- LiDAR -->
  <link name="lidar_link"/>
  <joint name="lidar_joint" type="fixed">
    <parent link="base_link"/>
    <child link="lidar_link"/>
    <origin xyz="0 0 0.1" rpy="0 0 0"/>
  </joint>

  <!-- Camera -->
  <link name="camera_link"/>
  <joint name="camera_joint" type="fixed">
    <parent link="base_link"/>
    <child link="camera_link"/>
    <origin xyz="0.15 0 0.1" rpy="0 0 0"/>
  </joint>

  <!-- Gazebo plugins -->
  <gazebo>
    <plugin name="diff_drive" filename="libgazebo_ros_diff_drive.so">
      <left_wheel>rear_left_wheel_joint</left_wheel>
      <right_wheel>rear_right_wheel_joint</right_wheel>
      <wheel_separation>0.24</wheel_separation>
      <wheel_radius>0.03</wheel_radius>
      <publish_wheel_tf>true</publish_wheel_tf>
      <robot_base_frame>base_link</robot_base_frame>
    </plugin>
  </gazebo>

  <gazebo reference="lidar_link">
    <sensor type="ray" name="lidar_sensor">
      <pose>0 0 0 0 0 0</pose>
      <ray>
        <scan>
          <horizontal>
            <samples>360</samples>
            <resolution>1</resolution>
            <min_angle>-3.14</min_angle>
            <max_angle>3.14</max_angle>
          </horizontal>
        </scan>
        <range>
          <min>0.12</min>
          <max>3.5</max>
        </range>
      </ray>
      <plugin name="lidar_plugin" filename="libgazebo_ros_ray_sensor.so">
        <topic_name>scan</topic_name>
        <frame_name>lidar_link</frame_name>
      </plugin>
    </sensor>
  </gazebo>

  <gazebo reference="camera_link">
    <sensor type="camera" name="camera_sensor">
      <camera>
        <horizontal_fov>1.0</horizontal_fov>
        <image>
          <width>640</width>
          <height>480</height>
          <format>R8G8B8</format>
        </image>
        <clip>
          <near>0.1</near>
          <far>100</far>
        </clip>
      </camera>
      <always_on>true</always_on>
      <update_rate>30.0</update_rate>
      <plugin name="camera_controller" filename="libgazebo_ros_camera.so">
        <camera_name>front_camera</camera_name>
        <image_topic_name>image_raw</image_topic_name>
        <camera_info_topic_name>camera_info</camera_info_topic_name>
        <frame_name>camera_link</frame_name>
      </plugin>
    </sensor>
  </gazebo>

</robot>
