<?xml version="1.0"?>
<robot xmlns:xacro="http://www.ros.org/wiki/xacro" name="delivery_bot">

  <!-- Macros for simplifying wheel creation -->
  <xacro:macro name="wheel" params="prefix x y">
    <link name="${prefix}_wheel">
      <visual>
        <geometry>
          <cylinder length="0.05" radius="0.05"/>
        </geometry>
        <origin xyz="0 0 0" rpy="0 0 0"/>
        <material name="black"/>
      </visual>
      <collision>
        <geometry>
          <cylinder length="0.05" radius="0.05"/>
        </geometry>
        <origin xyz="0 0 0" rpy="0 0 0"/>
      </collision>
      <inertial>
        <mass value="0.2"/>
        <inertia ixx="0.001" ixy="0.0" ixz="0.0" iyy="0.001" iyz="0.0" izz="0.001"/>
      </inertial>
    </link>

    <joint name="${prefix}_joint" type="continuous">
      <parent link="base_link"/>
      <child link="${prefix}_wheel"/>
      <origin xyz="${x} ${y} -0.05" rpy="0 0 0"/>
      <axis xyz="0 1 0"/>
      <limit effort="5" velocity="10"/>
    </joint>

    <transmission name="${prefix}_trans">
      <type>transmission_interface/SimpleTransmission</type>
      <joint name="${prefix}_joint">
        <hardwareInterface>hardware_interface/VelocityJointInterface</hardwareInterface>
      </joint>
      <actuator name="${prefix}_motor">
        <hardwareInterface>hardware_interface/VelocityJointInterface</hardwareInterface>
        <mechanicalReduction>1</mechanicalReduction>
      </actuator>
    </transmission>
  </xacro:macro>

  <!-- Base -->
  <link name="base_link">
    <visual>
      <geometry>
        <box size="0.4 0.3 0.2"/>
      </geometry>
      <origin xyz="0 0 0.1" rpy="0 0 0"/>
      <material name="blue"/>
    </visual>
    <collision>
      <geometry>
        <box size="0.4 0.3 0.2"/>
      </geometry>
      <origin xyz="0 0 0.1" rpy="0 0 0"/>
    </collision>
    <inertial>
      <mass value="3.0"/>
      <inertia ixx="0.03" ixy="0" ixz="0" iyy="0.03" iyz="0" izz="0.03"/>
    </inertial>
  </link>

  <!-- Wheels -->
  <xacro:wheel prefix="rear_left" x="-0.15" y="0.15"/>
  <xacro:wheel prefix="rear_right" x="-0.15" y="-0.15"/>
  <xacro:wheel prefix="front_left" x="0.15" y="0.15"/>
  <xacro:wheel prefix="front_right" x="0.15" y="-0.15"/>

  <!-- Camera -->
  <link name="camera_link">
    <visual>
      <geometry>
        <box size="0.05 0.05 0.05"/>
      </geometry>
      <origin xyz="0.2 0 0.25" rpy="0 0 0"/>
      <material name="black"/>
    </visual>
  </link>

  <joint name="camera_joint" type="fixed">
    <parent link="base_link"/>
    <child link="camera_link"/>
    <origin xyz="0.2 0 0.25" rpy="0 0 0"/>
  </joint>

  <gazebo reference="camera_link">
    <sensor name="camera_sensor" type="camera">
      <camera>
        <horizontal_fov>1.3962634</horizontal_fov>
        <image>
          <width>640</width>
          <height>480</height>
          <format>R8G8B8</format>
        </image>
        <clip>
          <near>0.1</near>
          <far>100</far>
        </clip>
      </camera>
      <always_on>true</always_on>
      <update_rate>30</update_rate>
      <visualize>true</visualize>
      <plugin name="camera_controller" filename="libgazebo_ros_camera.so">
        <camera_name>rgb_camera</camera_name>
        <image_topic_name>image_raw</image_topic_name>
        <camera_info_topic_name>camera_info</camera_info_topic_name>
        <frame_name>camera_link</frame_name>
      </plugin>
    </sensor>
  </gazebo>

  <!-- LiDAR -->
  <link name="lidar_link">
    <visual>
      <geometry>
        <cylinder length="0.05" radius="0.04"/>
      </geometry>
      <origin xyz="0 0 0.3" rpy="0 0 0"/>
      <material name="gray"/>
    </visual>
  </link>

  <joint name="lidar_joint" type="fixed">
    <parent link="base_link"/>
    <child link="lidar_link"/>
    <origin xyz="0 0 0.3" rpy="0 0 0"/>
  </joint>

  <gazebo reference="lidar_link">
    <sensor name="lidar_sensor" type="ray">
      <ray>
        <scan>
          <horizontal>
            <samples>360</samples>
            <resolution>1</resolution>
            <min_angle>-3.14</min_angle>
            <max_angle>3.14</max_angle>
          </horizontal>
        </scan>
        <range>
          <min>0.12</min>
          <max>5.0</max>
        </range>
        <noise>
          <type>gaussian</type>
          <mean>0.0</mean>
          <stddev>0.01</stddev>
        </noise>
      </ray>
      <plugin name="gazebo_ros_laser_controller" filename="libgazebo_ros_ray_sensor.so">
        <topicName>scan</topicName>
        <frameName>lidar_link</frameName>
      </plugin>
    </sensor>
  </gazebo>

  <ros2_control name="DeliveryBotHardware" type="system">
  <hardware>
    <plugin>fake_components/GenericSystem</plugin>
  </hardware>
  <joint name="rear_left_joint">
    <command_interface name="velocity"/>
    <state_interface name="velocity"/>
    <state_interface name="position"/>
  </joint>
  <joint name="rear_right_joint">
    <command_interface name="velocity"/>
    <state_interface name="velocity"/>
    <state_interface name="position"/>
  </joint>
</ros2_control>

</robot>
